<!DOCTYPE html>
<html class="no-js" lang="en">
<head>
	<meta charset="UTF-8">
	<meta name="viewport" content="width=device-width, initial-scale=1">
	<title>java try throw exception finally 遇上 return break continue造成异常丢失 - IT学习者博客</title>
	<script>(function(d,e){d[e]=d[e].replace("no-js","js");})(document.documentElement,"className");</script>
	<meta name="description" content="">
		<meta property="og:title" content="java try throw exception finally 遇上 return break continue造成异常丢失" />
<meta property="og:description" content="如下所示，是一个java笔试题，考察的是抛出异常之后，程序运行结果，但是这里抛出异常，并没有捕获异常，而是通过finally来进行了流程控制处理。
package com.xxx.test; public class ExceptionFlow { public static void main(String[] args) { try { System.out.println(&#34;hello &#34; &#43; func()); } catch (Exception e) { e.printStackTrace(); } } public static int func() { int a = 0; for (int i = 0; i &lt; 3; i&#43;&#43;) { try { throw new RuntimeException(&#34;xx&#34;); } finally { continue; } } return a; } } 运行程序，打印结果如下所示：
这里结果有些出人意料，并没有打印异常信息，其实就是try finally遇到了continue，导致异常信息丢失。如果这里，我们稍微改变一下，把finally中的continue注释，再来看看结果：
这次打印了异常信息。
下面再来看看另一个例子：
package com.xxx.test; public class ExceptionDemo { public static void main(String[] args) { try { func(); System." />
<meta property="og:type" content="article" />
<meta property="og:url" content="https://itnewbiea.github.io/posts/c3b958a3b676c40195e2c6fa2b84b7e6/" /><meta property="article:section" content="posts" />
<meta property="article:published_time" content="2023-10-30T00:07:46+08:00" />
<meta property="article:modified_time" content="2023-10-30T00:07:46+08:00" />


	<link rel="preconnect" href="https://fonts.gstatic.com" crossorigin>
	<link rel="dns-prefetch" href="//fonts.googleapis.com">
	<link rel="dns-prefetch" href="//fonts.gstatic.com">
	<link rel="stylesheet" href="https://fonts.googleapis.com/css?family=Open+Sans:400,400i,700">

	<link rel="stylesheet" href="/css/style.css">
	

	<link rel="shortcut icon" href="/favicon.ico">
		
</head>
<body class="body">
	<div class="container container--outer">
		<header class="header">
	<div class="container header__container">
		
	<div class="logo">
		<a class="logo__link" href="/" title="IT学习者博客" rel="home">
			<div class="logo__item logo__text">
					<div class="logo__title">IT学习者博客</div>
					
				</div>
		</a>
	</div>
		<div class="divider"></div>
	</div>
</header>
		<div class="wrapper flex">
			<div class="primary">
			
<main class="main" role="main">
	<article class="post">
		<header class="post__header">
			<h1 class="post__title">java try throw exception finally 遇上 return break continue造成异常丢失</h1>
			
		</header>
		<div class="content post__content clearfix">
			
<div id="content_views" class="htmledit_views">
                    <p>    如下所示，是一个java笔试题，考察的是抛出异常之后，程序运行结果，但是这里抛出异常，并没有捕获异常，而是通过finally来进行了流程控制处理。</p> 
<pre><code class="language-java">package com.xxx.test;

public class ExceptionFlow {
    public static void main(String[] args) {
        try {
            System.out.println("hello " + func());
        } catch (Exception e) {
            e.printStackTrace();
        }
    }

    public static int func() {
        int a = 0;
        for (int i = 0; i &lt; 3; i++) {
            try {
                throw new RuntimeException("xx");
            } finally {
                 continue;
            }
        }
        return a;
    }
}</code></pre> 
<p>    运行程序，打印结果如下所示：</p> 
<p style="text-align:center;"><img alt="" class="left" src="https://images2.imgbox.com/e8/af/5i3hzZ6E_o.png"> </p> 
<p>    这里结果有些出人意料，并没有打印异常信息，其实就是try finally遇到了continue，导致异常信息丢失。如果这里，我们稍微改变一下，把finally中的continue注释，再来看看结果：</p> 
<p style="text-align:center;"><img alt="" class="left" src="https://images2.imgbox.com/3e/a9/5EXDXY9A_o.png"> </p> 
<p>    这次打印了异常信息。</p> 
<p>   下面再来看看另一个例子：</p> 
<pre><code class="language-java">package com.xxx.test;
public class ExceptionDemo {
    public static void main(String[] args) {
        try {
            func();
            System.out.println("A");
        } catch (Exception e) {
            System.out.println("C");
        }
        System.out.println("D");
    }

    public static void func() {
        try {
            throw new Exception();
        } finally {
            System.out.println("B");
        }
    }
}
</code></pre> 
<p>    这里要求写出程序运行结果。</p> 
<p>    这道题的答案其实就是编译不通过，如下所示：</p> 
<p style="text-align:center;"><img alt="" class="left" src="https://images2.imgbox.com/59/5c/X0fK0nrQ_o.png"> </p> 
<p>    这里需要在func方法签名上声明抛出异常。方法签名上添加了抛出异常，这里就编译成功，运行结果是B C D。</p> 
<p>    这里其实也可以不用在方法签名上进行声明，直接把异常改成自定义异常RuntimeException("xx")，最终程序运行结果也是一样的。 </p> 
<p>    这里我们按照第一个题目的思路，把finally中添加return信息，这时候，运行结果会变为B A D。</p> 
<p style="text-align:center;"><img alt="" class="left" src="https://images2.imgbox.com/d1/f3/LgkuBUFr_o.png"></p> 
<p>   因为异常信息丢失，所以在调用func()的地方，进行try catch的时候，就不会有异常信息，那么程序就会按照正常的流程运行。 </p>
                </div>
		</div>
	</article>
</main>


<nav class="pager flex">
	<div class="pager__item pager__item--prev">
		<a class="pager__link" href="/posts/1c488e334a40a74af35f6a63ad96f571/" rel="prev">
			<span class="pager__subtitle">«&thinsp;Previous</span>
			<p class="pager__title">python中的with</p>
		</a>
	</div>
	<div class="pager__item pager__item--next">
		<a class="pager__link" href="/posts/ac83ec9f48486240f1c92d50eb6d89e5/" rel="next">
			<span class="pager__subtitle">Next&thinsp;»</span>
			<p class="pager__title">python中的迭代器</p>
		</a>
	</div>
</nav>


			</div>
			
		</div>
		<footer class="footer">
	<div class="container footer__container flex">
		
		<div class="footer__copyright">
			&copy; 2024 IT学习者博客.
			<span class="footer__copyright-credits">Generated with <a href="https://gohugo.io/" rel="nofollow noopener" target="_blank">Hugo</a> and <a href="https://github.com/Vimux/Mainroad/" rel="nofollow noopener" target="_blank">Mainroad</a> theme.</span>
		</div>
	</div>
</footer>
<script src="https://itnewbiea.github.io/js/foot.js"></script>


	</div>
<script async defer src="/js/menu.js"></script>
</body>
</html>